Workbook

Sheet Data Sources
A1: ID | B1: Cadence | C1: Batch Job | D1: Run Time (ET) | E1: Run Time (PT) | F1: Calls / Run | G1: Runs / Month | H1: Calls / Month | I1: Priority | J1: Current Cost ($/mo) | K1: Paid Plan (if needed) | L1: Paid Plan Cost ($/mo) | M1: Likelihood of Paying | N1: Likelihood Band | O1: Expected Cost ($/mo) | P1: Cost Trigger | Q1: Category | R1: Data Item | S1: Source | T1: Access Type | U1: Endpoint / URL | V1: Example Params / Notes on Call | W1: Auth | X1: Cost / Limits | Y1: Format | Z1: Role | AA1: Notes | AB1: Schedule Note | AC1: Holiday Calendar
A2: DS-02 | B2: Hourly | C2: H1 | D2: Hourly at :05, 10:05–16:05 (early-close days: 10:05–13:05) | E2: Hourly at :05, 07:05–13:05 (early-close days: 07:05–10:05) | F2: 1 | G2: 145.91667 | H2: =F2*G2 -> 145.91667 | I2: P1 | J2: 0 | K2: Not used – free tier only ($0 data budget) | L2: 0 | M2: 0 | N2: =IF(L2=0,"None",IF(M2>0.6,"High",IF(M2>0.2,"Medium","Low"))) -> None | O2: =J2+(L2-J2)*M2 -> 0 | P2: Use free IEX feed; full-market volume not required for hourly trend | Q2: Stock price | R2: Hourly bars: TSLA, SPCX + index/sector ETF proxies (SPY, DIA, QQQ, IWM, XLY, ITA, SMH) + any user-added tickers (primary) | S2: Alpaca Market Data | T2: REST | U2: https://data.alpaca.markets/v2/stocks/bars?symbols=TSLA,SPCX,SPY,DIA,QQQ,IWM,XLY,ITA,SMH&timeframe=1Hour&feed=iex | V2: Both tickers in one call; snapshots: /v2/stocks/snapshots?symbols=TSLA,SPCX | W2: API key + secret (free account) | X2: Free Basic plan (IEX feed, 200 calls/min) | Y2: JSON | Z2: Primary | AA2: FREE-TIER IMPACT: now the primary price source; ETF proxies ride in the same call (still 1 call/run). Prices match the consolidated tape closely; volume is IEX-only (a small share of total volume), so volume charts show trend, not true totals. No real-time SIP feed. | AB2: Primary: one multi-symbol call returns hourly bars for TSLA, SPCX and the 7 ETF proxies (union of all users' tickers) | AC2: US-MKT (NYSE trading days)
A3: DS-35 | B3: Hourly | C3: H2 | D3: Hourly at :15, 24 runs | E3: Hourly at :15, 24 runs | F3: 1 | G3: 502 | H3: =F3*G3 -> 502 | I3: P2 | J3: 0 | K3: Free – no paid plan needed | L3: 0 | M3: 0 | N3: =IF(L3=0,"None",IF(M3>0.6,"High",IF(M3>0.2,"Medium","Low"))) -> None | O3: =J3+(L3-J3)*M3 -> 0 | Q3: Geopolitical | R3: Global news events, tone, themes | S3: GDELT DOC 2.0 API | T3: REST | U3: https://api.gdeltproject.org/api/v2/doc/doc?query=(tariff OR sanctions OR Taiwan) sourcelang:english&mode=artlist&format=json&timespan=1h | V3: mode=timelinetone for sentiment trend | W3: None | X3: Free | Y3: JSON | Z3: Primary | AA3: Updates every 15 min; noisy, needs filtering | AB3: One combined query (tariff OR sanctions OR Taiwan OR ...) | AC3: US-MKT (NYSE trading days)
A4: DS-40 | B4: Hourly | C4: H2 | D4: Hourly at :15, 06:15–21:15 only (16 runs) | E4: Hourly at :15, 03:15–18:15 only (16 runs) | F4: 1 | G4: 334.66667 | H4: =F4*G4 -> 334.66667 | I4: P2 | J4: 0 | K4: Not used – free tier only ($0 data budget) | L4: 0 | M4: 0 | N4: =IF(L4=0,"None",IF(M4>0.6,"High",IF(M4>0.2,"Medium","Low"))) -> None | O4: =J4+(L4-J4)*M4 -> 0 | P4: Stay on free 25 calls/day: news polling capped at 16 calls/day | Q4: Financial news | R4: Ticker news + sentiment (union of all users' tickers, rotated) | S4: Alpha Vantage NEWS_SENTIMENT | T4: REST | U4: https://www.alphavantage.co/query?function=NEWS_SENTIMENT&tickers={TICKER}&apikey={KEY} | V4: One ticker per call (multiple tickers narrow results to articles mentioning all of them); rotation e.g. TSLA, SPCX, TSLA, SPCX… then user-added tickers | W4: API key | X4: Free 25 calls/day (capped at 16/day by schedule) | Y4: JSON | Z4: Primary | AA4: FREE-TIER IMPACT: capped at 16 calls/day (06:15–21:15 ET) to stay under the free 25/day. Collectors read the union of all users' tickers but sentiment rotates one ticker per call (fixed list or rotation), so each ticker refreshes every few hours, not hourly; no overnight updates. | AB4: One ticker per run from a fixed rotation over the union of users' tickers; hard cap 16/day (free limit 25) | AC4: US-MKT (NYSE trading days)
A5: DS-41 | B5: Hourly | C5: H2 | D5: Hourly at :15, 24 runs | E5: Hourly at :15, 24 runs | F5: 2 | G5: 502 | H5: =F5*G5 -> 1004 | I5: P1 | J5: 0 | K5: Free – no paid plan needed | L5: 0 | M5: 0 | N5: =IF(L5=0,"None",IF(M5>0.6,"High",IF(M5>0.2,"Medium","Low"))) -> None | O5: =J5+(L5-J5)*M5 -> 0 | Q5: Financial news | R5: Company news | S5: Finnhub | T5: REST | U5: https://finnhub.io/api/v1/company-news?symbol=TSLA&from={d}&to={d}&token={KEY} | V5: General: /news?category=general | W5: API key | X5: Free | Y5: JSON | Z5: Primary | AB5: TSLA + SPCX; also covers DS-78 | AC5: US-MKT (NYSE trading days)
A6: DS-44 | B6: Hourly | C6: H2 | D6: Hourly at :15, 24 runs | E6: Hourly at :15, 24 runs | F6: 3 | G6: 502 | H6: =F6*G6 -> 1506 | I6: P2 | J6: 0 | K6: Free – no paid plan needed | L6: 0 | M6: 0 | N6: =IF(L6=0,"None",IF(M6>0.6,"High",IF(M6>0.2,"Medium","Low"))) -> None | O6: =J6+(L6-J6)*M6 -> 0 | Q6: Financial news | R6: Headline RSS | S6: Google News RSS | T6: RSS | U6: https://news.google.com/rss/search?q=Tesla+stock&hl=en-US&gl=US&ceid=US:en | V6: Separate feeds for SpaceX, Fed, tariffs | W6: None | X6: Free | Y6: RSS XML | Z6: Fallback | AA6: No sentiment; aggregator links | AB6: 3 queries: Tesla, SpaceX/Starlink/Starship, Robotaxi/Cybercab; also covers DS-79 | AC6: US-MKT (NYSE trading days)
A7: DS-77 | B7: Hourly | C7: H2 | D7: Hourly at :15, 24 runs | E7: Hourly at :15, 24 runs | F7: 1 | G7: 502 | H7: =F7*G7 -> 502 | I7: P2 | J7: 0 | K7: Free – no paid plan needed | L7: 0 | M7: 0 | N7: =IF(L7=0,"None",IF(M7>0.6,"High",IF(M7>0.2,"Medium","Low"))) -> None | O7: =J7+(L7-J7)*M7 -> 0 | Q7: SpaceX news | R7: Space-industry articles & reports linked to launches | S7: Spaceflight News API (SNAPI) v4 | T7: REST | U7: https://api.spaceflightnewsapi.net/v4/articles/?search=SpaceX&ordering=-published_at | V7: Also /v4/reports/, /v4/blogs/; filter launch=<LL2 launch id> | W7: None | X7: Free | Y7: JSON | Z7: Primary | AA7: Same org as Launch Library 2, IDs link across | AC7: US-MKT (NYSE trading days)
A8: DS-06 | B8: Hourly | C8: H3 | D8: Hourly at :25, 06:25–22:25 | E8: Hourly at :25, 03:25–19:25 | F8: 1 | G8: 354.16667 | H8: =F8*G8 -> 354.16667 | I8: P1 | J8: 0 | K8: Free – no paid plan needed | L8: 0 | M8: 0 | N8: =IF(L8=0,"None",IF(M8>0.6,"High",IF(M8>0.2,"Medium","Low"))) -> None | O8: =J8+(L8-J8)*M8 -> 0 | Q8: SpaceX valuation / listing | R8: SPCX listing details, share count, lock-up, filings | S8: SEC EDGAR (company_tickers + submissions) | T8: REST | U8: https://www.sec.gov/files/company_tickers.json -> https://data.sec.gov/submissions/CIK{10-digit CIK}.json | V8: Resolve SPCX CIK from company_tickers.json; S-1/424B4 prospectus, Form 4 insider trades, 13D/G | W8: None (User-Agent header with email required) | X8: Free | Y8: JSON | Z8: Primary | AA8: SpaceX listed on Nasdaq as SPCX on 12 Jun 2026; track lock-up expiry dates from prospectus | AB8: One EDGAR submissions call for SPCX catches new 8-K, Form 4, 10-Q | AC8: US-FED (US federal business days)
A9: DS-08 | B9: Hourly | C9: H3 | D9: Hourly at :25, 06:25–22:25 | E9: Hourly at :25, 03:25–19:25 | F9: 1 | G9: 354.16667 | H9: =F9*G9 -> 354.16667 | I9: P2 | J9: 0 | K9: Not used – free tier only ($0 data budget) | L9: 0 | M9: 0 | N9: =IF(L9=0,"None",IF(M9>0.6,"High",IF(M9>0.2,"Medium","Low"))) -> None | O9: =J9+(L9-J9)*M9 -> 0 | P9: Free 15 calls/hour; we use 1/hour | Q9: SpaceX operations | R9: Launch schedule & outcomes (Starship, Falcon, Starlink) | S9: The Space Devs – Launch Library 2 | T9: REST | U9: https://ll.thespacedevs.com/2.3.0/launches/upcoming/?lsp__name=SpaceX | V9: Also /launches/previous/; dev mirror lldev.thespacedevs.com for testing | W9: None (key for higher limits) | X9: Free 15 req/hr; Patreon tiers | Y9: JSON | Z9: Primary | AA9: FREE-TIER IMPACT: none – free 15 calls/hour; schedule uses 1/hour. | AB9: One call returns all upcoming SpaceX launches | AC9: US-FED (US federal business days)
A10: DS-09 | B10: Hourly | C10: H3 | D10: Hourly at :25, 06:25–22:25 | E10: Hourly at :25, 03:25–19:25 | F10: 1 | G10: 354.16667 | H10: =F10*G10 -> 354.16667 | I10: P3 | J10: 0 | K10: Free – no paid plan needed | L10: 0 | M10: 0 | N10: =IF(L10=0,"None",IF(M10>0.6,"High",IF(M10>0.2,"Medium","Low"))) -> None | O10: =J10+(L10-J10)*M10 -> 0 | Q10: SpaceX operations | R10: Company updates | S10: SpaceX website | T10: Web | U10: https://www.spacex.com/updates/ | V10: Scrape/monitor for new posts | W10: None | X10: Free | Y10: HTML | Z10: Secondary | AC10: US-FED (US federal business days)
A11: DS-10 | B11: Hourly | C11: H3 | D11: Hourly at :25, 06:25–22:25 | E11: Hourly at :25, 03:25–19:25 | F11: 1 | G11: 354.16667 | H11: =F11*G11 -> 354.16667 | I11: P1 | J11: 0 | K11: Free – no paid plan needed | L11: 0 | M11: 0 | N11: =IF(L11=0,"None",IF(M11>0.6,"High",IF(M11>0.2,"Medium","Low"))) -> None | O11: =J11+(L11-J11)*M11 -> 0 | Q11: Tesla fundamentals | R11: Filings: 10-Q, 10-K, 8-K, Form 4 | S11: SEC EDGAR | T11: REST + Atom | U11: https://data.sec.gov/submissions/CIK0001318605.json | V11: Atom: https://www.sec.gov/cgi-bin/browse-edgar?action=getcompany&CIK=0001318605&type=8-K&output=atom | W11: None (User-Agent header required) | X11: Free | Y11: JSON / Atom XML | Z11: Primary | AA11: Tesla CIK = 0001318605 | AB11: One EDGAR submissions call for TSLA | AC11: US-FED (US federal business days)
A12: DS-18 | B12: Hourly | C12: H3 | D12: Hourly at :25, 06:25–22:25 | E12: Hourly at :25, 03:25–19:25 | F12: 1 | G12: 354.16667 | H12: =F12*G12 -> 354.16667 | I12: P1 | J12: 0 | K12: Free – no paid plan needed | L12: 0 | M12: 0 | N12: =IF(L12=0,"None",IF(M12>0.6,"High",IF(M12>0.2,"Medium","Low"))) -> None | O12: =J12+(L12-J12)*M12 -> 0 | Q12: Interest rates | R12: FOMC statements, minutes, press releases | S12: Federal Reserve | T12: RSS | U12: https://www.federalreserve.gov/feeds/press_monetary.xml | V12: All releases: /feeds/press_all.xml; Speeches: /feeds/speeches.xml | W12: None | X12: Free | Y12: RSS XML | Z12: Primary | AA12: Decision released 2:00pm ET on meeting day | AB12: Plus one extra run at 14:05 ET on FOMC decision days | AC12: US-FED (US federal business days)
A13: DS-27 | B13: Hourly | C13: H3 | D13: Hourly at :25, 06:25–22:25 | E13: Hourly at :25, 03:25–19:25 | F13: 1 | G13: 354.16667 | H13: =F13*G13 -> 354.16667 | I13: P1 | J13: 0 | K13: Free – no paid plan needed | L13: 0 | M13: 0 | N13: =IF(L13=0,"None",IF(M13>0.6,"High",IF(M13>0.2,"Medium","Low"))) -> None | O13: =J13+(L13-J13)*M13 -> 0 | Q13: Tariffs | R13: Tariff rules, Section 301/232 notices, exclusions | S13: Federal Register API | T13: REST | U13: https://www.federalregister.gov/api/v1/documents.json?conditions[term]=tariff&conditions[agencies][]=trade-representative-office-of-united-states&order=newest | V13: Also agencies: international-trade-administration, industry-and-security-bureau, customs-and-border-protection | W13: None | X13: Free | Y13: JSON | Z13: Primary | AA13: Most structured source for legal tariff actions | AB13: One query combines tariff terms + USTR/ITA/BIS/CBP agencies; also covers DS-49 | AC13: US-FED (US federal business days)
A14: DS-28 | B14: Hourly | C14: H3 | D14: Hourly at :25, 06:25–22:25 | E14: Hourly at :25, 03:25–19:25 | F14: 1 | G14: 354.16667 | H14: =F14*G14 -> 354.16667 | I14: P1 | J14: 0 | K14: Free – no paid plan needed | L14: 0 | M14: 0 | N14: =IF(L14=0,"None",IF(M14>0.6,"High",IF(M14>0.2,"Medium","Low"))) -> None | O14: =J14+(L14-J14)*M14 -> 0 | Q14: Tariffs | R14: Presidential tariff proclamations & executive orders | S14: White House | T14: Web | U14: https://www.whitehouse.gov/presidential-actions/ | V14: Monitor for 'tariff', 'Section 232', 'IEEPA' | W14: None | X14: Free | Y14: HTML | Z14: Primary | AA14: Often appears before Federal Register publication | AC14: US-FED (US federal business days)
A15: DS-29 | B15: Hourly | C15: H3 | D15: Hourly at :25, 06:25–22:25 | E15: Hourly at :25, 03:25–19:25 | F15: 1 | G15: 354.16667 | H15: =F15*G15 -> 354.16667 | I15: P1 | J15: 0 | K15: Free – no paid plan needed | L15: 0 | M15: 0 | N15: =IF(L15=0,"None",IF(M15>0.6,"High",IF(M15>0.2,"Medium","Low"))) -> None | O15: =J15+(L15-J15)*M15 -> 0 | Q15: Tariffs | R15: USTR press releases (trade deals, Section 301) | S15: USTR | T15: Web | U15: https://ustr.gov/about-us/policy-offices/press-office/press-releases | W15: None | X15: Free | Y15: HTML | Z15: Primary | AC15: US-FED (US federal business days)
A16: DS-72 | B16: Hourly | C16: H3 | D16: Hourly at :25, 06:25–22:25 | E16: Hourly at :25, 03:25–19:25 | F16: 1 | G16: 354.16667 | H16: =F16*G16 -> 354.16667 | I16: P1 | J16: 0 | K16: Free – no paid plan needed | L16: 0 | M16: 0 | N16: =IF(L16=0,"None",IF(M16>0.6,"High",IF(M16>0.2,"Medium","Low"))) -> None | O16: =J16+(L16-J16)*M16 -> 0 | Q16: SpaceX contracts | R16: NASA contract awards (Artemis HLS, Crew/Cargo, launch services) | S16: NASA News Releases | T16: RSS | U16: https://www.nasa.gov/news-release/feed/ | V16: Filter titles for 'contract', 'SpaceX', 'award' | W16: None | X16: Free | Y16: RSS XML | Z16: Primary | AC16: US-FED (US federal business days)
A17: DS-13 | B17: Daily | C17: D1 | D17: 07:00 | E17: 04:00 | F17: 2 | G17: 20.833333 | H17: =F17*G17 -> 41.666667 | I17: P2 | J17: 0 | K17: Free – no paid plan needed | L17: 0 | M17: 0 | N17: =IF(L17=0,"None",IF(M17>0.6,"High",IF(M17>0.2,"Medium","Low"))) -> None | O17: =J17+(L17-J17)*M17 -> 0 | Q17: Earnings calendar | R17: TSLA & SPCX earnings dates, EPS estimates | S17: Finnhub | T17: REST | U17: https://finnhub.io/api/v1/calendar/earnings?symbol=TSLA&from={d}&to={d}&token={KEY} | W17: API key | X17: Free | Y17: JSON | Z17: Primary | AA17: Alt: Alpha Vantage function=EARNINGS_CALENDAR | AB17: TSLA + SPCX | AC17: US-MKT (NYSE trading days)
A18: DS-15 | B18: Daily | C18: D1 | D18: 07:00 | E18: 04:00 | F18: 6 | G18: 20.833333 | H18: =F18*G18 -> 125 | I18: P1 | J18: 0 | K18: Free – no paid plan needed | L18: 0 | M18: 0 | N18: =IF(L18=0,"None",IF(M18>0.6,"High",IF(M18>0.2,"Medium","Low"))) -> None | O18: =J18+(L18-J18)*M18 -> 0 | Q18: Bond yields | R18: 2Y, 10Y, 30Y yields; 10Y–2Y spread; real yields | S18: FRED (St. Louis Fed) | T18: REST | U18: https://api.stlouisfed.org/fred/series/observations?series_id=DGS10&api_key={KEY}&file_type=json | V18: series_id = DGS2, DGS10, DGS30, T10Y2Y, DFII10 (see Series IDs tab) | W18: API key (free) | X18: Free | Y18: JSON | Z18: Primary | AA18: Simplest single API for all macro series | AB18: DGS2, DGS10, DGS30, T10Y2Y, DFII10, T10YIE | AC18: US-FED (US federal business days)
A19: DS-16 | B19: Daily | C19: D1 | D19: 07:00 | E19: 04:00 | F19: 3 | G19: 20.833333 | H19: =F19*G19 -> 62.5 | I19: P1 | J19: 0 | K19: Free – no paid plan needed | L19: 0 | M19: 0 | N19: =IF(L19=0,"None",IF(M19>0.6,"High",IF(M19>0.2,"Medium","Low"))) -> None | O19: =J19+(L19-J19)*M19 -> 0 | Q19: Interest rates | R19: Fed funds target range (upper/lower), effective rate | S19: FRED | T19: REST | U19: https://api.stlouisfed.org/fred/series/observations?series_id=DFEDTARU&api_key={KEY}&file_type=json | V19: DFEDTARU, DFEDTARL, EFFR | W19: API key | X19: Free | Y19: JSON | Z19: Primary | AB19: DFEDTARU, DFEDTARL, EFFR | AC19: US-FED (US federal business days)
A20: DS-26 | B20: Daily | C20: D1 | D20: 07:00 | E20: 04:00 | F20: 1 | G20: 20.833333 | H20: =F20*G20 -> 20.833333 | I20: P2 | J20: 0 | K20: Free – no paid plan needed | L20: 0 | M20: 0 | N20: =IF(L20=0,"None",IF(M20>0.6,"High",IF(M20>0.2,"Medium","Low"))) -> None | O20: =J20+(L20-J20)*M20 -> 0 | Q20: Economic calendar | R20: Release dates for any FRED series | S20: FRED Releases API | T20: REST | U20: https://api.stlouisfed.org/fred/releases/dates?api_key={KEY}&file_type=json&realtime_start={today} | W20: API key | X20: Free | Y20: JSON | Z20: Backup | AA20: FREE-TIER IMPACT: promoted to primary for release dates (CPI, PCE, jobs). Gives dates only – no consensus values. | AB20: Source for release-day triggers (CPI, PCE) – replaces paid calendar | AC20: US-FED (US federal business days)
A21: DS-39 | B21: Daily | C21: D1 | D21: 07:00 | E21: 04:00 | F21: 1 | G21: 20.833333 | H21: =F21*G21 -> 20.833333 | I21: P3 | J21: 0 | K21: Free – no paid plan needed | L21: 0 | M21: 0 | N21: =IF(L21=0,"None",IF(M21>0.6,"High",IF(M21>0.2,"Medium","Low"))) -> None | O21: =J21+(L21-J21)*M21 -> 0 | Q21: Geopolitical | R21: Economic Policy Uncertainty index (daily) | S21: FRED | T21: REST | U21: https://api.stlouisfed.org/fred/series/observations?series_id=USEPUINDXD&api_key={KEY}&file_type=json | W21: API key | X21: Free | Y21: JSON | Z21: Secondary | AC21: US-FED (US federal business days)
A22: DS-45 | B22: Daily | C22: D1 | D22: 07:00 | E22: 04:00 | F22: 3 | G22: 20.833333 | H22: =F22*G22 -> 62.5 | I22: P3 | J22: 0 | K22: Free – no paid plan needed | L22: 0 | M22: 0 | N22: =IF(L22=0,"None",IF(M22>0.6,"High",IF(M22>0.2,"Medium","Low"))) -> None | O22: =J22+(L22-J22)*M22 -> 0 | Q22: Market context | R22: VIX, US Dollar Index, WTI oil | S22: FRED | T22: REST | U22: https://api.stlouisfed.org/fred/series/observations?series_id=VIXCLS&api_key={KEY}&file_type=json | V22: VIXCLS, DTWEXBGS, DCOILWTICO | W22: API key | X22: Free | Y22: JSON | Z22: Optional | AA22: Risk-sentiment overlays | AB22: VIXCLS, DTWEXBGS, DCOILWTICO | AC22: US-FED (US federal business days)
A23: DS-88 | B23: Daily | C23: D1 | D23: 07:00 | E23: 04:00 | F23: 1 | G23: 20.833333 | H23: =F23*G23 -> 20.833333 | I23: P2 | J23: 0 | K23: Free – no paid plan needed | L23: 0 | M23: 0 | N23: =IF(L23=0,"None",IF(M23>0.6,"High",IF(M23>0.2,"Medium","Low"))) -> None | O23: =J23+(L23-J23)*M23 -> 0 | Q23: Interest rates | R23: Market-implied fed funds rate probabilities (replaces CME FedWatch) | S23: Atlanta Fed Market Probability Tracker | T23: Web + data download | U23: https://www.atlantafed.org/cenfis/market-probability-tracker | V23: Historical data download link on the page; RSS: https://www.atlantafed.org/RSS/MarketProbabilityTracker | W23: None | X23: Free | Y23: XLSX/CSV | Z23: Primary | AA23: Derived from CME SOFR options; updated each business day with prior-day data. Quarterly horizons, not meeting-by-meeting | AB23: Prior-day data available by morning | AC23: US-FED (US federal business days)
A24: DS-31 | B24: Daily | C24: D2 | D24: 07:30 | E24: 04:30 | F24: 1 | G24: 20.833333 | H24: =F24*G24 -> 20.833333 | I24: P2 | J24: 0 | K24: Free – no paid plan needed | L24: 0 | M24: 0 | N24: =IF(L24=0,"None",IF(M24>0.6,"High",IF(M24>0.2,"Medium","Low"))) -> None | O24: =J24+(L24-J24)*M24 -> 0 | Q24: Tariffs | R24: CBP implementation notices (CSMS) | S24: US Customs & Border Protection | T24: Web / email | U24: https://www.cbp.gov/trade/automated/cargo-systems-messaging-service | W24: None | X24: Free | Y24: HTML | Z24: Secondary | AA24: Effective-date details for collection | AC24: US-FED (US federal business days)
A25: DS-32 | B25: Daily | C25: D2 | D25: 07:30 | E25: 04:30 | F25: 1 | G25: 20.833333 | H25: =F25*G25 -> 20.833333 | I25: P2 | J25: 0 | K25: Free – no paid plan needed | L25: 0 | M25: 0 | N25: =IF(L25=0,"None",IF(M25>0.6,"High",IF(M25>0.2,"Medium","Low"))) -> None | O25: =J25+(L25-J25)*M25 -> 0 | Q25: Tariffs | R25: Export controls (chips, batteries, critical minerals) | S25: Commerce – BIS | T25: Web | U25: https://www.bis.gov/news-updates | V25: Also via Federal Register agency=industry-and-security-bureau | W25: None | X25: Free | Y25: HTML | Z25: Secondary | AC25: US-FED (US federal business days)
A26: DS-33 | B26: Daily | C26: D2 | D26: 07:30 | E26: 04:30 | F26: 1 | G26: 20.833333 | H26: =F26*G26 -> 20.833333 | I26: P3 | J26: 0 | K26: Free – no paid plan needed | L26: 0 | M26: 0 | N26: =IF(L26=0,"None",IF(M26>0.6,"High",IF(M26>0.2,"Medium","Low"))) -> None | O26: =J26+(L26-J26)*M26 -> 0 | Q26: Tariffs | R26: China counter-measures (rare earths, export bans) | S26: China MOFCOM | T26: Web | U26: http://english.mofcom.gov.cn/ | W26: None | X26: Free | Y26: HTML | Z26: Secondary | AA26: English site lags Chinese site | AC26: CN (China State Council holidays)
A27: DS-37 | B27: Daily | C27: D2 | D27: 07:30 | E27: 04:30 | F27: 1 | G27: 20.833333 | H27: =F27*G27 -> 20.833333 | I27: P2 | J27: 0 | K27: Free – no paid plan needed | L27: 0 | M27: 0 | N27: =IF(L27=0,"None",IF(M27>0.6,"High",IF(M27>0.2,"Medium","Low"))) -> None | O27: =J27+(L27-J27)*M27 -> 0 | Q27: Geopolitical | R27: US sanctions actions | S27: Treasury OFAC | T27: Web / data files | U27: https://ofac.treasury.gov/recent-actions | V27: SDN list download: https://sanctionslist.ofac.treas.gov/ | W27: None | X27: Free | Y27: HTML / XML | Z27: Primary | AC27: US-FED (US federal business days)
A28: DS-47 | B28: Daily | C28: D2 | D28: 07:30 | E28: 04:30 | F28: 1 | G28: 20.833333 | H28: =F28*G28 -> 20.833333 | I28: P1 | J28: 0 | K28: Free – no paid plan needed | L28: 0 | M28: 0 | N28: =IF(L28=0,"None",IF(M28>0.6,"High",IF(M28>0.2,"Medium","Low"))) -> None | O28: =J28+(L28-J28)*M28 -> 0 | Q28: Robotaxi – US federal | R28: Defect investigations, audit queries, special orders (e.g., Cybercab AQ26002) | S28: NHTSA Office of Defects Investigation | T28: CSV (zip) + Web | U28: https://static.nhtsa.gov/odi/ffdd/inv/FLAT_INV.zip | V28: Search UI: https://www.nhtsa.gov/recalls (make=TESLA); press: https://www.nhtsa.gov/press-releases | W28: None | X28: Free | Y28: TXT/CSV | Z28: Primary | AA28: Investigation openings/escalations are price-moving | AC28: US-FED (US federal business days)
A29: DS-48 | B29: Daily | C29: D2 | D29: 07:30 | E29: 04:30 | F29: 3 | G29: 20.833333 | H29: =F29*G29 -> 62.5 | I29: P2 | J29: 0 | K29: Free – no paid plan needed | L29: 0 | M29: 0 | N29: =IF(L29=0,"None",IF(M29>0.6,"High",IF(M29>0.2,"Medium","Low"))) -> None | O29: =J29+(L29-J29)*M29 -> 0 | Q29: Robotaxi – US federal | R29: Recalls & complaints for Tesla models | S29: NHTSA vPIC / Recalls API | T29: REST | U29: https://api.nhtsa.gov/recalls/recallsByVehicle?make=TESLA&model=MODEL%20Y&modelYear=2026 | V29: Complaints: https://api.nhtsa.gov/complaints/complaintsByVehicle?make=TESLA&model=CYBERCAB&modelYear=2026 | W29: None | X29: Free | Y29: JSON | Z29: Primary | AB29: Model Y, Model 3, Cybercab | AC29: US-FED (US federal business days)
A30: DS-60 | B30: Daily | C30: D2 | D30: 07:30 | E30: 04:30 | F30: 1 | G30: 20.833333 | H30: =F30*G30 -> 20.833333 | I30: P1 | J30: 0 | K30: Free – no paid plan needed | L30: 0 | M30: 0 | N30: =IF(L30=0,"None",IF(M30>0.6,"High",IF(M30>0.2,"Medium","Low"))) -> None | O30: =J30+(L30-J30)*M30 -> 0 | Q30: Robotaxi – company | R30: Service areas, cities, app availability | S30: Tesla Robotaxi site / X account | T30: Web | U30: https://www.tesla.com/robotaxi | V30: Also official X: @robotaxi and @Tesla_AI for area expansions | W30: None | X30: Free | Y30: HTML | Z30: Primary | AA30: Tesla doesn't publish fleet size; quarterly letters give cumulative miles | AC30: US-FED (US federal business days)
A31: DS-61 | B31: Daily | C31: D2 | D31: 07:30 | E31: 04:30 | F31: 1 | G31: 20.833333 | H31: =F31*G31 -> 20.833333 | I31: P3 | J31: 0 | K31: Free – no paid plan needed | L31: 0 | M31: 0 | N31: =IF(L31=0,"None",IF(M31>0.6,"High",IF(M31>0.2,"Medium","Low"))) -> None | O31: =J31+(L31-J31)*M31 -> 0 | Q31: Robotaxi – trackers | R31: Aggregated state permit rosters & fleet sizes (Tesla, Waymo, Zoox) | S31: Robotaxi Tracker | T31: Web | U31: https://robotaxitracker.com/permits | V31: Methodology: https://robotaxitracker.com/methodology | W31: None | X31: Free (attribution required) | Y31: HTML | Z31: Secondary | AA31: Unofficial – cross-check against TxDMV/CA DMV | AC31: US-FED (US federal business days)
A32: DS-64 | B32: Daily | C32: D2 | D32: 07:30 | E32: 04:30 | F32: 1 | G32: 20.833333 | H32: =F32*G32 -> 20.833333 | I32: P1 | J32: 0 | K32: Free – no paid plan needed | L32: 0 | M32: 0 | N32: =IF(L32=0,"None",IF(M32>0.6,"High",IF(M32>0.2,"Medium","Low"))) -> None | O32: =J32+(L32-J32)*M32 -> 0 | Q32: SpaceX launches | R32: FAA launch/reentry licenses, Starship license mods, mishap investigations | S32: FAA Office of Commercial Space Transportation | T32: Web | U32: https://www.faa.gov/space/licenses/operator_licenses_permits | V32: Data: https://www.faa.gov/data_research/commercial_space_data ; Starship: https://www.faa.gov/space/stakeholder_engagement/spacex_starship | W32: None | X32: Free | Y32: HTML | Z32: Primary | AA32: Groundings after mishaps move SPCX | AC32: US-FED (US federal business days)
A33: DS-65 | B33: Daily | C33: D2 | D33: 07:30 | E33: 04:30 | F33: 1 | G33: 20.833333 | H33: =F33*G33 -> 20.833333 | I33: P2 | J33: 0 | K33: Free – no paid plan needed | L33: 0 | M33: 0 | N33: =IF(L33=0,"None",IF(M33>0.6,"High",IF(M33>0.2,"Medium","Low"))) -> None | O33: =J33+(L33-J33)*M33 -> 0 | Q33: SpaceX launches | R33: Starlink constellation size (on-orbit satellites) | S33: CelesTrak | T33: REST | U33: https://celestrak.org/NORAD/elements/gp.php?GROUP=starlink&FORMAT=json | V33: Count objects per day for constellation growth | W33: None | X33: Free | Y33: JSON | Z33: Primary | AA33: Space-Track.org is the authoritative alt (free account) | AB33: CelesTrak asks for ≤1 download per 2 hours; daily is well within | AC33: US-FED (US federal business days)
A34: DS-71 | B34: Daily | C34: D2 | D34: 07:30 | E34: 04:30 | F34: 1 | G34: 20.833333 | H34: =F34*G34 -> 20.833333 | I34: P2 | J34: 0 | K34: Free – no paid plan needed | L34: 0 | M34: 0 | N34: =IF(L34=0,"None",IF(M34>0.6,"High",IF(M34>0.2,"Medium","Low"))) -> None | O34: =J34+(L34-J34)*M34 -> 0 | Q34: SpaceX contracts | R34: NSSL launch assignments & Space Force awards | S34: Space Systems Command | T34: Web | U34: https://www.ssc.spaceforce.mil/News | W34: None | X34: Free | Y34: HTML | Z34: Primary | AC34: US-FED (US federal business days)
A35: DS-74 | B35: Daily | C35: D2 | D35: 07:30 | E35: 04:30 | F35: 1 | G35: 20.833333 | H35: =F35*G35 -> 20.833333 | I35: P2 | J35: 0 | K35: Free – no paid plan needed | L35: 0 | M35: 0 | N35: =IF(L35=0,"None",IF(M35>0.6,"High",IF(M35>0.2,"Medium","Low"))) -> None | O35: =J35+(L35-J35)*M35 -> 0 | Q35: SpaceX customers | R35: Starlink licensing, spectrum, direct-to-cell filings | S35: FCC ECFS API + ICFS | T35: REST | U35: https://publicapi.fcc.gov/ecfs/filings?api_key={KEY}&q=SpaceX&sort=date_disseminated,DESC | V35: Satellite applications: https://licensing.fcc.gov/myibfs/ (ICFS); api.data.gov key | W35: API key (api.data.gov) | X35: Free | Y35: JSON | Z35: Primary | AA35: Spectrum approvals drive Starlink capacity | AC35: US-FED (US federal business days)
A36: DS-76 | B36: Daily | C36: D2 | D36: 07:30 | E36: 04:30 | F36: 1 | G36: 20.833333 | H36: =F36*G36 -> 20.833333 | I36: P2 | J36: 0 | K36: Free – no paid plan needed | L36: 0 | M36: 0 | N36: =IF(L36=0,"None",IF(M36>0.6,"High",IF(M36>0.2,"Medium","Low"))) -> None | O36: =J36+(L36-J36)*M36 -> 0 | Q36: SpaceX customers | R36: Commercial customer announcements (airlines, telcos, governments) | S36: Starlink updates | T36: Web | U36: https://www.starlink.com/updates | V36: Also Starlink business/aviation press pages | W36: None | X36: Free | Y36: HTML | Z36: Secondary | AC36: US-FED (US federal business days)
A37: DS-17 | B37: Daily | C37: D3 | D37: 09:15 | E37: 06:15 | F37: 2 | G37: 20.833333 | H37: =F37*G37 -> 41.666667 | I37: P2 | J37: 0 | K37: Free – no paid plan needed | L37: 0 | M37: 0 | N37: =IF(L37=0,"None",IF(M37>0.6,"High",IF(M37>0.2,"Medium","Low"))) -> None | O37: =J37+(L37-J37)*M37 -> 0 | Q37: Interest rates | R37: Effective Fed Funds Rate & SOFR | S37: NY Fed Markets API | T37: REST | U37: https://markets.newyorkfed.org/api/rates/unsecured/effr/last/1.json | V37: SOFR: /api/rates/secured/sofr/last/1.json | W37: None | X37: Free | Y37: JSON | Z37: Primary | AB37: EFFR + SOFR (published ~09:00 ET) | AC37: US-FED (US federal business days)
A38: DS-01 | B38: Daily | C38: D4 | D38: 16:45 | E38: 13:45 | F38: 9 | G38: 20.75 | H38: =F38*G38 -> 186.75 | I38: P3 | J38: 0 | K38: Not used – free tier only ($0 data budget) | L38: 0 | M38: 0 | N38: =IF(L38=0,"None",IF(M38>0.6,"High",IF(M38>0.2,"Medium","Low"))) -> None | O38: =J38+(L38-J38)*M38 -> 0 | P38: Alpaca free IEX hourly bars (DS-02) become primary; Massive free tier keeps the daily-close check | Q38: Stock price | R38: Official daily close for TSLA, SPCX + ETF proxies (verifies Alpaca) | S38: Massive (formerly Polygon.io) | T38: REST | U38: https://api.massive.com/v2/aggs/ticker/{TICKER}/prev | V38: One call per ticker after the close (9 tickers); throttle to 5 calls/min (~2 minutes per run) | W38: API key | X38: Free Basic tier (5 calls/min, end-of-day + 15-min delayed) | Y38: JSON | Z38: Backup | AA38: FREE-TIER IMPACT: demoted to backup. Free Basic gives end-of-day + 15-min delayed data at 5 calls/min – enough for a daily-close check (9 calls/day incl. ETF proxies, throttled over ~2 min) and hourly failover, not primary intraday use. Fallback for index closes: FRED (DS-91). | AB38: Free tier: daily close per ticker (TSLA, SPCX + 7 ETFs), throttled to 5/min; failover for hourly bars | AC38: US-BOND (SIFMA bond-market days)
A39: DS-14 | B39: Daily | C39: D4 | D39: 16:45 | E39: 13:45 | F39: 1 | G39: 20.75 | H39: =F39*G39 -> 20.75 | I39: P1 | J39: 0 | K39: Free – no paid plan needed | L39: 0 | M39: 0 | N39: =IF(L39=0,"None",IF(M39>0.6,"High",IF(M39>0.2,"Medium","Low"))) -> None | O39: =J39+(L39-J39)*M39 -> 0 | Q39: Bond yields | R39: Daily Treasury par yield curve (1M–30Y) | S39: US Treasury | T39: XML / CSV | U39: https://home.treasury.gov/resource-center/data-chart-center/interest-rates/pages/xml?data=daily_treasury_yield_curve&field_tdr_date_value=2026 | V39: CSV: .../daily-treasury-rates.csv/2026/all?type=daily_treasury_yield_curve | W39: None | X39: Free | Y39: XML/CSV | Z39: Primary | AA39: Authoritative source for curve | AB39: Whole yield curve in one call (published ~15:30 ET) | AC39: US-BOND (SIFMA bond-market days)
A40: DS-89 | B40: Daily | C40: D4 | D40: 16:45 | E40: 13:45 | F40: 2 | G40: 20.75 | H40: =F40*G40 -> 41.5 | I40: P2 | J40: 0 | K40: Free – no paid plan needed | L40: 0 | M40: 0 | N40: =IF(L40=0,"None",IF(M40>0.6,"High",IF(M40>0.2,"Medium","Low"))) -> None | O40: =J40+(L40-J40)*M40 -> 0 | Q40: Interest rates / Inflation | R40: Meeting-level Fed decision odds and CPI outcome odds | S40: Kalshi public market data API | T40: REST | U40: https://api.elections.kalshi.com/trade-api/v2/markets?series_ticker={SERIES}&status=open | V40: Find series via /trade-api/v2/series (e.g., Fed decision and CPI series); market data needs no login | W40: None for market data | X40: Free (~20 req/s) | Y40: JSON | Z40: Secondary | AA40: Prediction-market prices; thin markets can be noisy. Read-only use, no account needed | AB40: Fed decision series + CPI series | AC40: US-MKT (NYSE trading days)
...

Sheet Cost Summary
A1: Monthly data cost by priority
A2: Priority | B2: Meaning | C2: # Sources | D2: Current ($/mo) | E2: Worst Case – all paid plans ($/mo) | F2: Expected ($/mo, probability-weighted)
A3: P1 | B3: Must-have: dashboard is wrong or incomplete without it | C3: =COUNTIF('Data Sources'!$I$2:$I$94,A3) -> 30 | D3: =SUMIFS('Data Sources'!$J$2:$J$94,'Data Sources'!$I$2:$I$94,A3) -> 0 | E3: =SUMIFS('Data Sources'!$L$2:$L$94,'Data Sources'!$I$2:$I$94,A3) -> 0 | F3: =SUMIFS('Data Sources'!$O$2:$O$94,'Data Sources'!$I$2:$I$94,A3) -> 0
A4: P2 | B4: Should-have: improves signal; dashboard works without it | C4: =COUNTIF('Data Sources'!$I$2:$I$94,A4) -> 33 | D4: =SUMIFS('Data Sources'!$J$2:$J$94,'Data Sources'!$I$2:$I$94,A4) -> 0 | E4: =SUMIFS('Data Sources'!$L$2:$L$94,'Data Sources'!$I$2:$I$94,A4) -> 0 | F4: =SUMIFS('Data Sources'!$O$2:$O$94,'Data Sources'!$I$2:$I$94,A4) -> 0
A5: P3 | B5: Nice-to-have / backup / cross-check | C5: =COUNTIF('Data Sources'!$I$2:$I$94,A5) -> 24 | D5: =SUMIFS('Data Sources'!$J$2:$J$94,'Data Sources'!$I$2:$I$94,A5) -> 0 | E5: =SUMIFS('Data Sources'!$L$2:$L$94,'Data Sources'!$I$2:$I$94,A5) -> 0 | F5: =SUMIFS('Data Sources'!$O$2:$O$94,'Data Sources'!$I$2:$I$94,A5) -> 0
A6: TOTAL | C6: =SUM(C3:C5) -> 87 | D6: =SUM(D3:D5) -> 0 | E6: =SUM(E3:E5) -> 0 | F6: =SUM(F3:F5) -> 0
A8: Paid upgrades declined – free replacements in use
A9: ID | B9: Source | C9: Priority | D9: Paid Plan Declined | E9: Price Avoided ($/mo) | H9: Free Replacement / How the Free Tier Is Used
A10: DS-25 | B10: Finnhub | C10: P1 | D10: FMP Premium / Finnhub premium economic calendar | E10: 59 | H10: Release dates: BLS schedule (DS-22) + FRED releases (DS-26). Expectations: Cleveland Fed nowcast (DS-90) + Kalshi CPI odds (DS-89)
A11: DS-01 | B11: Massive (formerly Polygon.io) | C11: P1 | D11: Massive Stocks Starter | E11: 29 | H11: Alpaca free IEX hourly bars (DS-02) become primary; Massive free tier keeps the daily-close check
A12: DS-20 | B12: CME FedWatch | C12: P2 | D12: CME FedWatch API – end of day | E12: 25 | H12: Atlanta Fed Market Probability Tracker (DS-88) + Kalshi Fed-decision odds (DS-89)
A13: DS-40 | B13: Alpha Vantage NEWS_SENTIMENT | C13: P2 | D13: Alpha Vantage Premium | E13: 49.99 | H13: Stay on free 25 calls/day: news polling capped at 16 calls/day
A14: DS-02 | B14: Alpaca Market Data | C14: P3 | D14: Alpaca Algo Trader Plus (SIP feed) | E14: 99 | H14: Use free IEX feed; full-market volume not required for hourly trend
A15: DS-43 | B15: NewsAPI | C15: P3 | D15: NewsAPI Business | E15: 449 | H15: Dropped – Finnhub company news (DS-41) + Google News RSS (DS-44)
A16: DS-08 | B16: The Space Devs – Launch Library 2 | C16: P2 | D16: Launch Library 2 Patreon tier (est.) | E16: 5 | H16: Free 15 calls/hour; we use 1/hour
A17: DS-36 | B17: ACLED API | C17: P3 | D17: ACLED Partner/Enterprise (unpriced) | E17: 0 | H17: Open tier (aggregated data) + GDELT events (DS-35)
A18: TOTAL AVOIDED | E18: =SUM(E10:E17) -> 715.99
A20: Policy (2026-10-03): $0 data budget – every source runs on its free tier. Paid Plan Cost and Likelihood of Paying are 0 on every row; to reconsider an upgrade, enter its price and likelihood on Data Sources and these totals recalculate.
A21: Trade-offs accepted: IEX-only volume (prices unaffected); quarterly-horizon rate odds from Atlanta Fed plus prediction-market odds instead of FedWatch meeting odds; Cleveland Fed nowcast instead of Wall Street consensus for CPI surprise; news capped at free limits.
A22: Prices checked 2026-10-03 from provider pricing pages / published summaries. FMP price is billed annually; Launch Library tier price is an estimate; ACLED commercial pricing is unpublished (excluded).
A23: Not included: hosting, database and scheduler costs for running the agents.

Sheet Batch Schedule
A1: Job | B1: Cadence | C1: Job Name | D1: Run Time (ET) | E1: Run Time (PT) | F1: Days | G1: Source IDs | H1: Runs / Month | I1: Calls / Run (sum) | J1: Calls / Month | K1: Avg Calls / Day | L1: Writes To | M1: Holiday Calendar
A2: H1 | B2: Hourly | C2: Market prices | D2: Hourly at :05, 10:05–16:05 (early-close days: 10:05–13:05) | E2: Hourly at :05, 07:05–13:05 (early-close days: 07:05–10:05) | F2: NYSE trading days only | G2: DS-02 | H2: 145.91667 | I2: =SUMIFS('Data Sources'!$F$2:$F$94,'Data Sources'!$C$2:$C$94,A2) -> 1 | J2: =SUMIFS('Data Sources'!$H$2:$H$94,'Data Sources'!$C$2:$C$94,A2) -> 145.91667 | K2: =J2/30 -> 4.8638889 | L2: prices_hourly (1-hour bars; last run = daily close) | M2: US-MKT (NYSE trading days)
A3: H2 | B3: Hourly | C3: News & sentiment | D3: Hourly at :15, 24 runs | E3: Hourly at :15, 24 runs | F3: NYSE trading days only; first run after a weekend/holiday pulls everything since the last run | G3: DS-35, DS-40, DS-41, DS-44, DS-77 | H3: 502 | I3: =SUMIFS('Data Sources'!$F$2:$F$94,'Data Sources'!$C$2:$C$94,A3) -> 8 | J3: =SUMIFS('Data Sources'!$H$2:$H$94,'Data Sources'!$C$2:$C$94,A3) -> 3848.6667 | K3: =J3/30 -> 128.28889 | L3: news_articles (dedupe on URL hash) | M3: US-MKT (NYSE trading days)
A4: H3 | B4: Hourly | C4: Regulatory & company feeds | D4: Hourly at :25, 06:25–22:25 | E4: Hourly at :25, 03:25–19:25 | F4: US federal business days; catch-up on first run after a gap | G4: DS-06, DS-08, DS-09, DS-10, DS-18, DS-27, DS-28, DS-29, DS-72 | H4: 354.16667 | I4: =SUMIFS('Data Sources'!$F$2:$F$94,'Data Sources'!$C$2:$C$94,A4) -> 9 | J4: =SUMIFS('Data Sources'!$H$2:$H$94,'Data Sources'!$C$2:$C$94,A4) -> 3187.5 | K4: =J4/30 -> 106.25 | L4: events (event_ts, type, source_url) + filings | M4: US-FED (US federal business days)
A5: D1 | B5: Daily | C5: Morning macro & calendars | D5: 07:00 | E5: 04:00 | F5: US federal business days | G5: DS-13, DS-15, DS-16, DS-26, DS-39, DS-45, DS-88 | H5: 20.833333 | I5: =SUMIFS('Data Sources'!$F$2:$F$94,'Data Sources'!$C$2:$C$94,A5) -> 17 | J5: =SUMIFS('Data Sources'!$H$2:$H$94,'Data Sources'!$C$2:$C$94,A5) -> 354.16667 | K5: =J5/30 -> 11.805556 | L5: macro_daily, release_calendar | M5: US-FED (US federal business days)
A6: D2 | B6: Daily | C6: Regulatory & operations sweep | D6: 07:30 | E6: 04:30 | F6: US federal business days; China/NL sources skipped on their own holidays | G6: DS-31, DS-32, DS-33, DS-37, DS-47, DS-48, DS-60, DS-61, DS-64, DS-65, DS-71, DS-74, DS-76 | H6: 20.833333 | I6: =SUMIFS('Data Sources'!$F$2:$F$94,'Data Sources'!$C$2:$C$94,A6) -> 15 | J6: =SUMIFS('Data Sources'!$H$2:$H$94,'Data Sources'!$C$2:$C$94,A6) -> 312.5 | K6: =J6/30 -> 10.416667 | L6: events, robotaxi_fleet, launches | M6: US-FED (US federal business days)
A7: D3 | B7: Daily | C7: Overnight rates | D7: 09:15 | E7: 06:15 | F7: US federal business days | G7: DS-17 | H7: 20.833333 | I7: =SUMIFS('Data Sources'!$F$2:$F$94,'Data Sources'!$C$2:$C$94,A7) -> 2 | J7: =SUMIFS('Data Sources'!$H$2:$H$94,'Data Sources'!$C$2:$C$94,A7) -> 41.666667 | K7: =J7/30 -> 1.3888889 | L7: macro_daily | M7: US-FED (US federal business days)
A8: D4 | B8: Daily | C8: Market close | D8: 16:45 | E8: 13:45 | F8: US bond-market (SIFMA) business days | G8: DS-01, DS-14, DS-89, DS-90, DS-93 | H8: 20.75 | I8: =SUMIFS('Data Sources'!$F$2:$F$94,'Data Sources'!$C$2:$C$94,A8) -> 15 | J8: =SUMIFS('Data Sources'!$H$2:$H$94,'Data Sources'!$C$2:$C$94,A8) -> 311.25 | K8: =J8/30 -> 10.375 | L8: macro_daily (yield curve, FedWatch odds) | M8: US-BOND (SIFMA bond-market days)
A9: D5 | B9: Daily | C9: Government contracts | D9: 17:45 | E9: 14:45 | F9: US federal business days | G9: DS-67, DS-68, DS-69, DS-70 | H9: 20.833333 | I9: =SUMIFS('Data Sources'!$F$2:$F$94,'Data Sources'!$C$2:$C$94,A9) -> 4 | J9: =SUMIFS('Data Sources'!$H$2:$H$94,'Data Sources'!$C$2:$C$94,A9) -> 83.333333 | K9: =J9/30 -> 2.7777778 | L9: contracts (award_id, agency, obligated $) | M9: US-FED (US federal business days)
A10: W1 | B10: Weekly | C10: Weekly sweep | D10: Mon 08:00 | E10: Mon 05:00 | F10: Monday; if Monday is a US federal holiday, runs the next business day | G10: DS-30, DS-36, DS-38, DS-50, DS-51, DS-54, DS-55, DS-56, DS-57, DS-58, DS-59, DS-62, DS-63, DS-66, DS-73 | H10: 4.33 | I10: =SUMIFS('Data Sources'!$F$2:$F$94,'Data Sources'!$C$2:$C$94,A10) -> 15 | J10: =SUMIFS('Data Sources'!$H$2:$H$94,'Data Sources'!$C$2:$C$94,A10) -> 64.95 | K10: =J10/30 -> 2.165 | L10: events, robotaxi_fleet, risk_indices | M10: US-FED (US federal business days)
A11: M1 | B11: Monthly / on release | C11: Release-triggered | D11: At release time (see Run Time); dates come from D1 calendars | E11: 3 hours earlier than ET | F11: Release days only (agencies don't release on holidays) | G11: DS-19, DS-21, DS-22, DS-24, DS-34, DS-46, DS-92 | H11: 1 | I11: =SUMIFS('Data Sources'!$F$2:$F$94,'Data Sources'!$C$2:$C$94,A11) -> 9 | J11: =SUMIFS('Data Sources'!$H$2:$H$94,'Data Sources'!$C$2:$C$94,A11) -> 10 | K11: =J11/30 -> 0.33333333 | L11: releases (actual, consensus, surprise, release_ts) | M11: Release calendar
A12: C1 | B12: Monthly / on release | C12: Calendar refresh | D12: 1st US federal business day of month, 06:00 | E12: 03:00 | F12: 1st US federal business day of month | G12: DS-80, DS-81, DS-82 | H12: 1 | I12: =SUMIFS('Data Sources'!$F$2:$F$94,'Data Sources'!$C$2:$C$94,A12) -> 1 | J12: =SUMIFS('Data Sources'!$H$2:$H$94,'Data Sources'!$C$2:$C$94,A12) -> 1 | K12: =J12/30 -> 0.033333333 | L12: calendar_days (date, calendar, is_open, close_time) | M12: US-FED (US federal business days)
A13: Q1 | B13: Quarterly | C13: Earnings & quarterly reports | D13: Earnings day 16:35 + next day 08:00 | E13: 13:35 + next day 05:00 | F13: Earnings / quarter-end (NYSE trading days) | G13: DS-11, DS-12, DS-53, DS-75 | H13: 0.33 | I13: =SUMIFS('Data Sources'!$F$2:$F$94,'Data Sources'!$C$2:$C$94,A13) -> 4 | J13: =SUMIFS('Data Sources'!$H$2:$H$94,'Data Sources'!$C$2:$C$94,A13) -> 1.66 | K13: =J13/30 -> 0.055333333 | L13: fundamentals_quarterly | M13: US-MKT (NYSE trading days)
... A17: X0 | B17: Not used / merged | C17: Not collected (paid) or merged into another call | D17: See Schedule Note | E17: — | F17: — | G17: DS-20, DS-25, DS-43, DS-49, DS-78, DS-79 | H17: 0 | I17: =SUMIFS('Data Sources'!$F$2:$F$94,'Data Sources'!$C$2:$C$94,A17) -> 0 | J17: =SUMIFS('Data Sources'!$H$2:$H$94,'Data Sources'!$C$2:$C$94,A17) -> 0 | K17: =J17/30 -> 0 | L17: — | M17: —
A18: TOTAL | J18: =SUM(J2:J17) -> 8363.0267 | K18: =SUM(K2:K17) -> 278.76756
A20: Free-tier limit check (typical day, after batching)
A21: Provider | B21: Free limit | C21: Our peak calls / day | D21: Headroom | G21: Source IDs
A22: Alpaca (free IEX + indicative options) | B22: 200 calls/min | C22: 9 | D22: OK | G22: DS-02 (7), DS-93 (2)
A23: Massive (free Basic) | B23: 5 calls/min | C23: 9 | D23: OK | G23: DS-01 (throttled: max 5/min)
A24: FINRA API (free) | B24: Not published – 1 call per publication | C24: 1 | D24: OK | G24: DS-92 (2/month)
A25: Kalshi (public data) | B25: ~20 calls/sec | C25: 2 | D25: OK | G25: DS-89
A26: Alpha Vantage | B26: 25 calls/day | C26: 16 | D26: OK | G26: DS-40
A27: Finnhub (free) | B27: 60 calls/min | C27: 50 | D27: OK | G27: DS-13, DS-41
A28: SAM.gov (basic key) | B28: 10 calls/day | C28: 2 | D28: OK | G28: DS-68, DS-69
A29: Launch Library 2 | B29: 15 calls/hour | C29: 17 | D29: OK — 1 call/hour vs 15/hour | G29: DS-08 (1/hour)
A30: FRED | B30: 120 calls/min | C30: 14 | D30: OK | G30: DS-15, 16, 39, 45
A31: SEC EDGAR | B31: 10 calls/sec | C31: 34 | D31: OK | G31: DS-06, DS-10
A32: BLS (with key) | B32: 500 calls/day | C32: 1 | D32: OK | G32: DS-21 (release days)

Sheet Holiday Calendar
A1: Date | B1: Day | C1: Calendar | D1: Holiday / Event | E1: Jobs Affected | F1: Sources Affected
A2: 46300 | B2: Mon | C2: CN | D2: China holiday – National Day (observed) | E2: D2 skips China sources | F2: DS-33, DS-59
A3: 46301 | B3: Tue | C3: CN | D3: China holiday – Day off (substituted from 09/20/2026) | E3: D2 skips China sources | F3: DS-33, DS-59
A4: 46302 | B4: Wed | C4: CN | D4: China holiday – Day off (substituted from 10/10/2026) | E4: D2 skips China sources | F4: DS-33, DS-59
A5: 46305 | B5: Sat | C5: CN | D5: China make-up workday (weekend working day) | E5: No US job runs on weekends; China sources picked up next US business day | F5: DS-33, DS-59
A6: 46307 | B6: Mon | C6: US-BOND | D6: Bond market closed (SIFMA) – Columbus Day | E6: D4 skips | F6: DS-14, DS-20
A7: 46307 | B7: Mon | C7: US-FED | D7: US federal holiday – Columbus Day | E7: H3, D1, D2, D3, D5 skip – W1 moves to Tue | F7: All US-FED sources
A8: 46337 | B8: Wed | C8: US-BOND | D8: Bond market closed (SIFMA) – Veterans Day | E8: D4 skips | F8: DS-14, DS-20
A9: 46337 | B9: Wed | C9: US-FED | D9: US federal holiday – Veterans Day | E9: H3, D1, D2, D3, D5 skip | F9: All US-FED sources
A10: 46352 | B10: Thu | C10: US-BOND | D10: Bond market closed (SIFMA) – Thanksgiving Day | E10: D4 skips | F10: DS-14, DS-20
A11: 46352 | B11: Thu | C11: US-FED | D11: US federal holiday – Thanksgiving Day | E11: H3, D1, D2, D3, D5 skip | F11: All US-FED sources
A12: 46352 | B12: Thu | C12: US-MKT | D12: NYSE closed – Thanksgiving Day | E12: H1, H2, Q1 skip | F12: All US-MKT sources
A13: 46353 | B13: Fri | C13: US-MKT | D13: NYSE early close (13:00 ET) | E13: H1 runs 10:05–13:05 ET only (last run = close) | F13: DS-01 and backups
... A73: 46752 | B73: Fri | C73: US-FED | D73: US federal holiday – New Year's Day (observed) | E73: H3, D1, D2, D3, D5 skip | F73: All US-FED sources
A75: Rule: no job runs on Saturday or Sunday. Each job also skips the holidays of the calendar named on its row in Data Sources / Batch Schedule.
A76: Generated 2026-10-03 from exchange_calendars (NYSE) and the holidays library (US federal, China, Netherlands). The agents use the same libraries at run time (DS-80, DS-81), so this list is for reference.
A77: US-FED holidays that fall on a weekday but not NYSE holidays (Columbus Day, Veterans Day): stock jobs run, federal and bond jobs skip.
A78: China 2027 dates are the library's projection; replace with the State Council notice when published (usually Nov–Dec 2026).
A79: Weekend-only holidays are not listed because nothing runs on weekends anyway.

Sheet Release Calendar
A1: Release | B1: Reference / Settlement Date | C1: Due Date | D1: Publication Date (collect) | E1: Job | F1: Source
A2: FINRA short interest | B2: 46295 | C2: 46297 | D2: 46304 | E2: M1 (08:00 ET next business day if after hours) | F2: DS-92
A3: FINRA short interest | B3: 46310 | C3: 46314 | D3: 46321 | E3: M1 (08:00 ET next business day if after hours) | F3: DS-92
A4: FINRA short interest | B4: 46325 | C4: 46329 | D4: 46336 | E4: M1 (08:00 ET next business day if after hours) | F4: DS-92
A5: FINRA short interest | B5: 46339 | C5: 46343 | D5: 46350 | E5: M1 (08:00 ET next business day if after hours) | F5: DS-92
A6: FINRA short interest | B6: 46356 | C6: 46358 | D6: 46365 | E6: M1 (08:00 ET next business day if after hours) | F6: DS-92
A7: FINRA short interest | B7: 46371 | C7: 46373 | D7: 46380 | E7: M1 (08:00 ET next business day if after hours) | F7: DS-92
A8: FINRA short interest | B8: 46387 | C8: 46392 | D8: 46399 | E8: M1 (08:00 ET next business day if after hours) | F8: DS-92
A9: FINRA short interest – rest of 2027 | B9: Pending | C9: Pending | D9: Mid-month and month-end settlements; FINRA publishes the next year's schedule late in the year – add when published | E9: M1 | F9: DS-92
A10: CPI, PCE, trade, FOMC | B10: — | C10: — | D10: Pulled automatically each morning by D1 from BLS schedule (DS-22) and FRED releases (DS-26) | E10: M1 | F10: DS-21, DS-24, DS-34
A11: Tesla deliveries | B11: Quarter end | C11: — | D11: ~2nd day after quarter end (UI plots on this release date) | E11: Q1 | F11: DS-12

Sheet Series IDs
A1: Provider | B1: Series / Code | C1: Description | D1: Frequency | E1: Category
A2: FRED | B2: DGS2 | C2: 2-Year Treasury yield | D2: Daily | E2: Bond yields
A3: FRED | B3: DGS10 | C3: 10-Year Treasury yield | D3: Daily | E3: Bond yields
A4: FRED | B4: DGS30 | C4: 30-Year Treasury yield | D4: Daily | E4: Bond yields
A5: FRED | B5: T10Y2Y | C5: 10Y minus 2Y spread | D5: Daily | E5: Bond yields
A6: FRED | B6: DFII10 | C6: 10-Year TIPS (real) yield | D6: Daily | E6: Bond yields
A7: FRED | B7: DFEDTARU | C7: Fed funds target – upper | D7: Daily | E7: Interest rates
A8: FRED | B8: DFEDTARL | C8: Fed funds target – lower | D8: Daily | E8: Interest rates
A9: FRED | B9: EFFR | C9: Effective fed funds rate | D9: Daily | E9: Interest rates
A10: FRED | B10: CPIAUCSL | C10: CPI-U all items, SA | D10: Monthly | E10: Inflation
A11: FRED | B11: CPILFESL | C11: Core CPI (ex food & energy), SA | D11: Monthly | E11: Inflation
A12: FRED | B12: PCEPI | C12: PCE price index | D12: Monthly | E12: Inflation
... A55: LL2 | B55: lsp__name=SpaceX | C55: Launch Library 2 provider filter | D55: Hourly | E55: SpaceX launches

Sheet Notes
A1: Investor Dashboard – Data Source Catalog
A2: Compiled 2026-10-03. Endpoints verified against public docs as of this date; free-tier limits change often — confirm before production use.
A3: Collection rule: nothing is polled more often than once an hour. Sources are sorted by cadence (Hourly → Daily → Weekly → Monthly/on release → Quarterly → Annual → One-time → Failover → Not used / merged), then by batch job and ID.
A4: Batching: each Batch Job runs all of its sources in one scheduled pass, so the scheduler wakes up 14 times a day rather than once per source. See the Batch Schedule tab for job times and call totals (formulas).
A5: Call-reduction rules applied: (1) multi-ticker / multi-term queries combined into one call where the API allows; (2) backups are polled only when the primary fails (Failover only = 0 calls normally); (3) duplicate sources merged (DS-49, DS-78, DS-79); (4) release data (CPI, PCE, trade) fetched once at release time, using dates pulled by job D1.
A6: Blue numbers (Calls / Run, Runs / Month) are editable assumptions; Calls / Month and the Batch Schedule totals recalculate. Runs / Month uses 251 NYSE trading days, 250 US federal business days and 249 bond-market days per year (2026 and 2027), divided by 12. Avg Calls / Day divides by 30 calendar days.
A7: No collection on weekends or holidays: every job follows the Holiday Calendar named on its row (see the Holiday Calendar tab). Regional sources (China MOFCOM/MIIT, Netherlands RDW) are also skipped on that country's holidays. Weekly jobs move to the next business day; feeds catch up on the first run after a gap, so nothing is lost.
A8: Times are US Eastern (source release times are published in ET); PT column = ET − 3 hours.
A9: {KEY} = your API key; {d} = date YYYY-MM-DD; {TICKER} = any tracked ticker.
A10: Ticker scope: collectors read the UNION of all users' tickers (default TSLA, SPCX + ETF proxies SPY, DIA, QQQ, IWM, XLY, ITA, SMH). Alpaca and Massive scale by adding symbols to the same calls; Alpha Vantage sentiment stays capped at 16 calls/day using a fixed list or rotation, so more tickers = less frequent sentiment per ticker.
A11: New ticker added by a user: run the DS-05 5-year daily backfill once for that ticker, then it joins the hourly (DS-02) and daily-close (DS-01) calls.
A12: SEC EDGAR requires a descriptive User-Agent header (name + email) and ≤10 requests/second.
... A15: $0 data budget: all sources use free tiers; paid upgrades declined are listed on the Cost Summary tab with their free replacements. Cost: see Cost Summary tab. Priority P1/P2/P3 and Likelihood of Paying are on each Data Sources row; expected monthly cost is probability-weighted.
